/home/tford/.conda-envs/geospatial/lib/python3.9/site-packages/xarray/core/dataset.py:277: UserWarning: The specified chunks separate the stored chunks along dimension "phony_dim_1" starting at index 500. This could degrade performance. Instead, consider rechunking after loading.
  warnings.warn(
Traceback (most recent call last):
  File "/home/tford/.conda-envs/geospatial/lib/python3.9/site-packages/xarray/backends/file_manager.py", line 211, in _acquire_with_cache_info
    file = self._cache[self._key]
  File "/home/tford/.conda-envs/geospatial/lib/python3.9/site-packages/xarray/backends/lru_cache.py", line 56, in __getitem__
    value = self._cache[key]
KeyError: [<class 'netCDF4._netCDF4.Dataset'>, ('/projects/inspire/PySAM-MAPS/test-all-states/colorado/09/416245-534475.nc',), 'a', (('clobber', True), ('diskless', False), ('format', 'NETCDF4'), ('persist', False)), '0cc405f0-c4aa-4941-acc0-c45179ea80f7']

During handling of the above exception, another exception occurred:

Traceback (most recent call last):
  File "/home/tford/dev/InSPIRE/Studies/USMap_Doubleday_2024/inspire-agrivolt-package/inspire_agrivolt/irradiance_sam.py", line 164, in process_slice
    partial_res.to_netcdf(fname)
  File "/home/tford/.conda-envs/geospatial/lib/python3.9/site-packages/xarray/core/dataset.py", line 2329, in to_netcdf
    return to_netcdf(  # type: ignore  # mypy cannot resolve the overloads:(
  File "/home/tford/.conda-envs/geospatial/lib/python3.9/site-packages/xarray/backends/api.py", line 1369, in to_netcdf
    writes = writer.sync(compute=compute)
  File "/home/tford/.conda-envs/geospatial/lib/python3.9/site-packages/xarray/backends/common.py", line 267, in sync
    delayed_store = chunkmanager.store(
  File "/home/tford/.conda-envs/geospatial/lib/python3.9/site-packages/xarray/namedarray/daskmanager.py", line 249, in store
    return store(
  File "/home/tford/.conda-envs/geospatial/lib/python3.9/site-packages/dask/array/core.py", line 1229, in store
    compute_as_if_collection(Array, store_dsk, map_keys, **kwargs)
  File "/home/tford/.conda-envs/geospatial/lib/python3.9/site-packages/dask/base.py", line 403, in compute_as_if_collection
    return schedule(dsk2, keys, **kwargs)
  File "/home/tford/.conda-envs/geospatial/lib/python3.9/site-packages/distributed/client.py", line 3484, in get
    results = self.gather(packed, asynchronous=asynchronous, direct=direct)
  File "/home/tford/.conda-envs/geospatial/lib/python3.9/site-packages/distributed/client.py", line 2567, in gather
    return self.sync(
  File "/home/tford/.conda-envs/geospatial/lib/python3.9/site-packages/xarray/backends/netCDF4_.py", line 78, in __setitem__
    data = self.get_array(needs_lock=False)
  File "/home/tford/.conda-envs/geospatial/lib/python3.9/site-packages/xarray/backends/netCDF4_.py", line 91, in get_array
    ds = self.datastore._acquire(needs_lock)
  File "/home/tford/.conda-envs/geospatial/lib/python3.9/site-packages/xarray/backends/netCDF4_.py", line 411, in _acquire
    with self._manager.acquire_context(needs_lock) as root:
  File "/home/tford/.conda-envs/geospatial/lib/python3.9/contextlib.py", line 119, in __enter__
    return next(self.gen)
  File "/home/tford/.conda-envs/geospatial/lib/python3.9/site-packages/xarray/backends/file_manager.py", line 199, in acquire_context
    file, cached = self._acquire_with_cache_info(needs_lock)
  File "/home/tford/.conda-envs/geospatial/lib/python3.9/site-packages/xarray/backends/file_manager.py", line 217, in _acquire_with_cache_info
    file = self._opener(*self._args, **kwargs)
  File "src/netCDF4/_netCDF4.pyx", line 2470, in netCDF4._netCDF4.Dataset.__init__
  File "src/netCDF4/_netCDF4.pyx", line 2107, in netCDF4._netCDF4._ensure_nc_success
OSError: [Errno -101] NetCDF: HDF error: '/projects/inspire/PySAM-MAPS/test-all-states/colorado/09/416245-534475.nc'

The above exception was the direct cause of the following exception:

Traceback (most recent call last):
  File "/home/tford/.conda-envs/geospatial/bin/agrivolt_ground_irradiance", line 8, in <module>
    sys.exit(ground_irradiance())
  File "/home/tford/dev/InSPIRE/Studies/USMap_Doubleday_2024/inspire-agrivolt-package/inspire_agrivolt/main.py", line 142, in ground_irradiance
    irradiance_sam.run_state(
  File "/home/tford/dev/InSPIRE/Studies/USMap_Doubleday_2024/inspire-agrivolt-package/inspire_agrivolt/irradiance_sam.py", line 255, in run_state
    compute(*batch)
  File "/home/tford/.conda-envs/geospatial/lib/python3.9/site-packages/dask/base.py", line 662, in compute
    results = schedule(dsk, keys, **kwargs)
  File "/home/tford/dev/InSPIRE/Studies/USMap_Doubleday_2024/inspire-agrivolt-package/inspire_agrivolt/irradiance_sam.py", line 170, in process_slice
    raise Exception(error_msg) from e
Exception: Error during task: Saving partial result to NetCDF file: /projects/inspire/PySAM-MAPS/test-all-states/colorado/09/416245-534475.nc
Original error: [Errno -101] NetCDF: HDF error: '/projects/inspire/PySAM-MAPS/test-all-states/colorado/09/416245-534475.nc'
